[2025-07-15T22:44:31.923+0000] {taskinstance.py:1956} INFO - Dependencies all met for dep_context=non-requeueable deps ti=<TaskInstance: curated_market_dq.validate_dataframe manual__2025-07-15T22:43:42.787201+00:00 [queued]>
[2025-07-15T22:44:31.973+0000] {taskinstance.py:1956} INFO - Dependencies all met for dep_context=requeueable deps ti=<TaskInstance: curated_market_dq.validate_dataframe manual__2025-07-15T22:43:42.787201+00:00 [queued]>
[2025-07-15T22:44:31.979+0000] {taskinstance.py:2170} INFO - Starting attempt 1 of 3
[2025-07-15T22:44:32.024+0000] {taskinstance.py:2191} INFO - Executing <Task(_PythonDecoratedOperator): validate_dataframe> on 2025-07-15 22:43:42.787201+00:00
[2025-07-15T22:44:32.052+0000] {standard_task_runner.py:60} INFO - Started process 489 to run task
[2025-07-15T22:44:32.059+0000] {standard_task_runner.py:87} INFO - Running: ['***', 'tasks', 'run', 'curated_market_dq', 'validate_dataframe', 'manual__2025-07-15T22:43:42.787201+00:00', '--job-id', '68', '--raw', '--subdir', 'DAGS_FOLDER/curated_market_dq_dag.py', '--cfg-path', '/tmp/tmpcbylr58g']
[2025-07-15T22:44:32.063+0000] {standard_task_runner.py:88} INFO - Job 68: Subtask validate_dataframe
[2025-07-15T22:44:32.176+0000] {task_command.py:423} INFO - Running <TaskInstance: curated_market_dq.validate_dataframe manual__2025-07-15T22:43:42.787201+00:00 [running]> on host 933e6b50c7ae
[2025-07-15T22:44:32.761+0000] {taskinstance.py:2480} INFO - Exporting env vars: AIRFLOW_CTX_DAG_OWNER='data-platform' AIRFLOW_CTX_DAG_ID='curated_market_dq' AIRFLOW_CTX_TASK_ID='validate_dataframe' AIRFLOW_CTX_EXECUTION_DATE='2025-07-15T22:43:42.787201+00:00' AIRFLOW_CTX_TRY_NUMBER='1' AIRFLOW_CTX_DAG_RUN_ID='manual__2025-07-15T22:43:42.787201+00:00'
[2025-07-15T22:44:32.770+0000] {taskinstance.py:2698} ERROR - Task failed with exception
Traceback (most recent call last):
  File "/home/airflow/.local/lib/python3.8/site-packages/airflow/models/taskinstance.py", line 433, in _execute_task
    result = execute_callable(context=context, **execute_callable_kwargs)
  File "/home/airflow/.local/lib/python3.8/site-packages/airflow/decorators/base.py", line 241, in execute
    return_value = super().execute(context)
  File "/home/airflow/.local/lib/python3.8/site-packages/airflow/operators/python.py", line 199, in execute
    return_value = self.execute_callable()
  File "/home/airflow/.local/lib/python3.8/site-packages/airflow/operators/python.py", line 216, in execute_callable
    return self.python_callable(*self.op_args, **self.op_kwargs)
  File "/opt/airflow/dags/curated_market_dq_dag.py", line 64, in validate_dataframe
    ctx = gx.get_context(project_root_dir=GE_PROJECT_ROOT)
  File "/home/airflow/.local/lib/python3.8/site-packages/great_expectations/data_context/data_context/context_factory.py", line 263, in get_context
    context = _get_context(**kwargs)
  File "/home/airflow/.local/lib/python3.8/site-packages/great_expectations/data_context/data_context/context_factory.py", line 302, in _get_context
    file_context = _get_file_context(
  File "/home/airflow/.local/lib/python3.8/site-packages/great_expectations/data_context/data_context/context_factory.py", line 383, in _get_file_context
    return FileDataContext(
  File "/home/airflow/.local/lib/python3.8/site-packages/great_expectations/data_context/data_context/file_data_context.py", line 64, in __init__
    self._scaffold_project()
  File "/home/airflow/.local/lib/python3.8/site-packages/great_expectations/data_context/data_context/file_data_context.py", line 98, in _scaffold_project
    self._scaffold(
  File "/home/airflow/.local/lib/python3.8/site-packages/great_expectations/data_context/data_context/serializable_data_context.py", line 219, in _scaffold
    gx_dir.mkdir(parents=True, exist_ok=True)
  File "/usr/local/lib/python3.8/pathlib.py", line 1288, in mkdir
    self._accessor.mkdir(self, mode)
PermissionError: [Errno 13] Permission denied: '/opt/airflow/gx/gx'
[2025-07-15T22:44:32.798+0000] {taskinstance.py:1138} INFO - Marking task as UP_FOR_RETRY. dag_id=curated_market_dq, task_id=validate_dataframe, execution_date=20250715T224342, start_date=20250715T224431, end_date=20250715T224432
[2025-07-15T22:44:32.829+0000] {standard_task_runner.py:107} ERROR - Failed to execute job 68 for task validate_dataframe ([Errno 13] Permission denied: '/opt/airflow/gx/gx'; 489)
[2025-07-15T22:44:32.865+0000] {local_task_job_runner.py:234} INFO - Task exited with return code 1
[2025-07-15T22:44:32.917+0000] {taskinstance.py:3280} INFO - 0 downstream tasks scheduled from follow-on schedule check
