[2025-07-13T15:37:24.330+0000] {taskinstance.py:1956} INFO - Dependencies all met for dep_context=non-requeueable deps ti=<TaskInstance: transform_market_data.transform_market_data manual__2025-07-13T15:37:15.739554+00:00 [queued]>
[2025-07-13T15:37:24.355+0000] {taskinstance.py:1956} INFO - Dependencies all met for dep_context=requeueable deps ti=<TaskInstance: transform_market_data.transform_market_data manual__2025-07-13T15:37:15.739554+00:00 [queued]>
[2025-07-13T15:37:24.357+0000] {taskinstance.py:2170} INFO - Starting attempt 1 of 2
[2025-07-13T15:37:24.394+0000] {taskinstance.py:2191} INFO - Executing <Task(PythonOperator): transform_market_data> on 2025-07-13 15:37:15.739554+00:00
[2025-07-13T15:37:24.422+0000] {standard_task_runner.py:60} INFO - Started process 533 to run task
[2025-07-13T15:37:24.429+0000] {standard_task_runner.py:87} INFO - Running: ['***', 'tasks', 'run', 'transform_market_data', 'transform_market_data', 'manual__2025-07-13T15:37:15.739554+00:00', '--job-id', '17', '--raw', '--subdir', 'DAGS_FOLDER/transform_market_data_dag.py', '--cfg-path', '/tmp/tmp0d1rykdu']
[2025-07-13T15:37:24.434+0000] {standard_task_runner.py:88} INFO - Job 17: Subtask transform_market_data
[2025-07-13T15:37:24.667+0000] {task_command.py:423} INFO - Running <TaskInstance: transform_market_data.transform_market_data manual__2025-07-13T15:37:15.739554+00:00 [running]> on host 26c08c9ca2cf
[2025-07-13T15:37:25.192+0000] {taskinstance.py:2480} INFO - Exporting env vars: AIRFLOW_CTX_DAG_OWNER='mark' AIRFLOW_CTX_DAG_ID='transform_market_data' AIRFLOW_CTX_TASK_ID='transform_market_data' AIRFLOW_CTX_EXECUTION_DATE='2025-07-13T15:37:15.739554+00:00' AIRFLOW_CTX_TRY_NUMBER='1' AIRFLOW_CTX_DAG_RUN_ID='manual__2025-07-13T15:37:15.739554+00:00'
[2025-07-13T15:37:25.276+0000] {credentials.py:1147} INFO - Found credentials in environment variables.
[2025-07-13T15:37:27.173+0000] {taskinstance.py:2698} ERROR - Task failed with exception
Traceback (most recent call last):
  File "/home/airflow/.local/lib/python3.8/site-packages/pandas/core/indexes/base.py", line 3653, in get_loc
    return self._engine.get_loc(casted_key)
  File "pandas/_libs/index.pyx", line 147, in pandas._libs.index.IndexEngine.get_loc
  File "pandas/_libs/index.pyx", line 176, in pandas._libs.index.IndexEngine.get_loc
  File "pandas/_libs/hashtable_class_helper.pxi", line 7080, in pandas._libs.hashtable.PyObjectHashTable.get_item
  File "pandas/_libs/hashtable_class_helper.pxi", line 7088, in pandas._libs.hashtable.PyObjectHashTable.get_item
KeyError: 'close'

The above exception was the direct cause of the following exception:

Traceback (most recent call last):
  File "/home/airflow/.local/lib/python3.8/site-packages/airflow/models/taskinstance.py", line 433, in _execute_task
    result = execute_callable(context=context, **execute_callable_kwargs)
  File "/home/airflow/.local/lib/python3.8/site-packages/airflow/operators/python.py", line 199, in execute
    return_value = self.execute_callable()
  File "/home/airflow/.local/lib/python3.8/site-packages/airflow/operators/python.py", line 216, in execute_callable
    return self.python_callable(*self.op_args, **self.op_kwargs)
  File "/opt/airflow/dags/transform_market_data_dag.py", line 24, in transform_yfinance_data
    df_pandas['rsi'] = ta.momentum.RSIIndicator(df_pandas['close']).rsi()
  File "/home/airflow/.local/lib/python3.8/site-packages/pandas/core/frame.py", line 3761, in __getitem__
    indexer = self.columns.get_loc(key)
  File "/home/airflow/.local/lib/python3.8/site-packages/pandas/core/indexes/base.py", line 3655, in get_loc
    raise KeyError(key) from err
KeyError: 'close'
[2025-07-13T15:37:27.495+0000] {taskinstance.py:1138} INFO - Marking task as UP_FOR_RETRY. dag_id=transform_market_data, task_id=transform_market_data, execution_date=20250713T153715, start_date=20250713T153724, end_date=20250713T153727
[2025-07-13T15:37:27.643+0000] {standard_task_runner.py:107} ERROR - Failed to execute job 17 for task transform_market_data ('close'; 533)
[2025-07-13T15:37:27.799+0000] {local_task_job_runner.py:234} INFO - Task exited with return code 1
[2025-07-13T15:37:27.902+0000] {taskinstance.py:3280} INFO - 0 downstream tasks scheduled from follow-on schedule check
