[2025-07-17T13:37:38.702+0000] {taskinstance.py:1956} INFO - Dependencies all met for dep_context=non-requeueable deps ti=<TaskInstance: curated_market_dq.publish_docs manual__2025-07-17T13:36:51.273895+00:00 [queued]>
[2025-07-17T13:37:38.722+0000] {taskinstance.py:1956} INFO - Dependencies all met for dep_context=requeueable deps ti=<TaskInstance: curated_market_dq.publish_docs manual__2025-07-17T13:36:51.273895+00:00 [queued]>
[2025-07-17T13:37:38.723+0000] {taskinstance.py:2170} INFO - Starting attempt 1 of 3
[2025-07-17T13:37:38.753+0000] {taskinstance.py:2191} INFO - Executing <Task(_PythonDecoratedOperator): publish_docs> on 2025-07-17 13:36:51.273895+00:00
[2025-07-17T13:37:38.765+0000] {standard_task_runner.py:60} INFO - Started process 12033 to run task
[2025-07-17T13:37:38.774+0000] {standard_task_runner.py:87} INFO - Running: ['***', 'tasks', 'run', 'curated_market_dq', 'publish_docs', 'manual__2025-07-17T13:36:51.273895+00:00', '--job-id', '130', '--raw', '--subdir', 'DAGS_FOLDER/curated_market_dq_dag.py', '--cfg-path', '/tmp/tmpwyx8n458']
[2025-07-17T13:37:38.776+0000] {standard_task_runner.py:88} INFO - Job 130: Subtask publish_docs
[2025-07-17T13:37:38.868+0000] {task_command.py:423} INFO - Running <TaskInstance: curated_market_dq.publish_docs manual__2025-07-17T13:36:51.273895+00:00 [running]> on host 189e939b6cc2
[2025-07-17T13:37:39.018+0000] {taskinstance.py:2480} INFO - Exporting env vars: AIRFLOW_CTX_DAG_OWNER='data-platform' AIRFLOW_CTX_DAG_ID='curated_market_dq' AIRFLOW_CTX_TASK_ID='publish_docs' AIRFLOW_CTX_EXECUTION_DATE='2025-07-17T13:36:51.273895+00:00' AIRFLOW_CTX_TRY_NUMBER='1' AIRFLOW_CTX_DAG_RUN_ID='manual__2025-07-17T13:36:51.273895+00:00'
[2025-07-17T13:37:39.063+0000] {credentials.py:1147} INFO - Found credentials in environment variables.
[2025-07-17T13:37:39.597+0000] {taskinstance.py:2698} ERROR - Task failed with exception
Traceback (most recent call last):
  File "/home/airflow/.local/lib/python3.8/site-packages/airflow/models/taskinstance.py", line 433, in _execute_task
    result = execute_callable(context=context, **execute_callable_kwargs)
  File "/home/airflow/.local/lib/python3.8/site-packages/airflow/decorators/base.py", line 241, in execute
    return_value = super().execute(context)
  File "/home/airflow/.local/lib/python3.8/site-packages/airflow/operators/python.py", line 199, in execute
    return_value = self.execute_callable()
  File "/home/airflow/.local/lib/python3.8/site-packages/airflow/operators/python.py", line 216, in execute_callable
    return self.python_callable(*self.op_args, **self.op_kwargs)
  File "/opt/airflow/dags/curated_market_dq_dag.py", line 101, in publish_docs
    for html_file in Path(local_site_path).rglob("*"):
  File "/usr/local/lib/python3.8/pathlib.py", line 1042, in __new__
    self = cls._from_parts(args, init=False)
  File "/usr/local/lib/python3.8/pathlib.py", line 683, in _from_parts
    drv, root, parts = self._parse_args(args)
  File "/usr/local/lib/python3.8/pathlib.py", line 667, in _parse_args
    a = os.fspath(a)
TypeError: expected str, bytes or os.PathLike object, not NoneType
[2025-07-17T13:37:39.777+0000] {taskinstance.py:1138} INFO - Marking task as UP_FOR_RETRY. dag_id=curated_market_dq, task_id=publish_docs, execution_date=20250717T133651, start_date=20250717T133738, end_date=20250717T133739
[2025-07-17T13:37:39.815+0000] {standard_task_runner.py:107} ERROR - Failed to execute job 130 for task publish_docs (expected str, bytes or os.PathLike object, not NoneType; 12033)
[2025-07-17T13:37:39.885+0000] {local_task_job_runner.py:234} INFO - Task exited with return code 1
[2025-07-17T13:37:39.976+0000] {taskinstance.py:3280} INFO - 0 downstream tasks scheduled from follow-on schedule check
