[2025-07-19T15:58:20.319+0000] {taskinstance.py:1956} INFO - Dependencies all met for dep_context=non-requeueable deps ti=<TaskInstance: build_ml_features.validate_features manual__2025-07-19T15:53:11.232887+00:00 [queued]>
[2025-07-19T15:58:20.322+0000] {taskinstance.py:1956} INFO - Dependencies all met for dep_context=requeueable deps ti=<TaskInstance: build_ml_features.validate_features manual__2025-07-19T15:53:11.232887+00:00 [queued]>
[2025-07-19T15:58:20.322+0000] {taskinstance.py:2170} INFO - Starting attempt 2 of 2
[2025-07-19T15:58:20.325+0000] {taskinstance.py:2191} INFO - Executing <Task(_PythonDecoratedOperator): validate_features> on 2025-07-19 15:53:11.232887+00:00
[2025-07-19T15:58:20.330+0000] {standard_task_runner.py:60} INFO - Started process 942 to run task
[2025-07-19T15:58:20.331+0000] {standard_task_runner.py:87} INFO - Running: ['***', 'tasks', 'run', 'build_ml_features', 'validate_features', 'manual__2025-07-19T15:53:11.232887+00:00', '--job-id', '159', '--raw', '--subdir', 'DAGS_FOLDER/build_ml_features_dag.py', '--cfg-path', '/tmp/tmpxo7z02mr']
[2025-07-19T15:58:20.332+0000] {standard_task_runner.py:88} INFO - Job 159: Subtask validate_features
[2025-07-19T15:58:20.348+0000] {task_command.py:423} INFO - Running <TaskInstance: build_ml_features.validate_features manual__2025-07-19T15:53:11.232887+00:00 [running]> on host 14bf87fd7a3d
[2025-07-19T15:58:20.376+0000] {taskinstance.py:2480} INFO - Exporting env vars: AIRFLOW_CTX_DAG_OWNER='data-platform' AIRFLOW_CTX_DAG_ID='build_ml_features' AIRFLOW_CTX_TASK_ID='validate_features' AIRFLOW_CTX_EXECUTION_DATE='2025-07-19T15:53:11.232887+00:00' AIRFLOW_CTX_TRY_NUMBER='2' AIRFLOW_CTX_DAG_RUN_ID='manual__2025-07-19T15:53:11.232887+00:00'
[2025-07-19T15:58:20.395+0000] {file_data_context.py:222} INFO - FileDataContext loading fluent config
[2025-07-19T15:58:20.396+0000] {config.py:187} INFO - Loading 'datasources' ->
[{'assets': [...], 'name': 'local_pandas', 'type': 'pandas'}]
[2025-07-19T15:58:20.396+0000] {fluent_base_model.py:276} INFO - _PandasDataAsset.dict() - missing `config_provider`, skipping config substitution
[2025-07-19T15:58:20.396+0000] {fluent_base_model.py:276} INFO - _PandasDataAsset.dict() - missing `config_provider`, skipping config substitution
[2025-07-19T15:58:20.408+0000] {abstract_data_context.py:5515} INFO - Loaded 'local_pandas' from fluent config
[2025-07-19T15:58:20.409+0000] {file_data_context.py:174} INFO - Saving 1 Fluent Datasources to /opt/***/gx/great_expectations.yml
[2025-07-19T15:58:20.409+0000] {fluent_base_model.py:276} INFO - DataFrameAsset.dict() - missing `config_provider`, skipping config substitution
[2025-07-19T15:58:20.409+0000] {fluent_base_model.py:276} INFO - DataFrameAsset.dict() - missing `config_provider`, skipping config substitution
[2025-07-19T15:58:20.409+0000] {fluent_base_model.py:276} INFO - PandasDatasource.dict() - missing `config_provider`, skipping config substitution
[2025-07-19T15:58:20.437+0000] {taskinstance.py:2698} ERROR - Task failed with exception
Traceback (most recent call last):
  File "/home/airflow/.local/lib/python3.8/site-packages/great_expectations/checkpoint/checkpoint.py", line 458, in _run_validation
    validate_validation_dict(
  File "/home/airflow/.local/lib/python3.8/site-packages/great_expectations/checkpoint/util.py", line 513, in validate_validation_dict
    raise gx_exceptions.CheckpointError("validation action_list cannot be empty")
great_expectations.exceptions.exceptions.CheckpointError: validation action_list cannot be empty

The above exception was the direct cause of the following exception:

Traceback (most recent call last):
  File "/home/airflow/.local/lib/python3.8/site-packages/airflow/models/taskinstance.py", line 433, in _execute_task
    result = execute_callable(context=context, **execute_callable_kwargs)
  File "/home/airflow/.local/lib/python3.8/site-packages/airflow/decorators/base.py", line 241, in execute
    return_value = super().execute(context)
  File "/home/airflow/.local/lib/python3.8/site-packages/airflow/operators/python.py", line 199, in execute
    return_value = self.execute_callable()
  File "/home/airflow/.local/lib/python3.8/site-packages/airflow/operators/python.py", line 216, in execute_callable
    return self.python_callable(*self.op_args, **self.op_kwargs)
  File "/opt/airflow/dags/build_ml_features_dag.py", line 91, in validate_features
    result = ctx.run_checkpoint(
  File "/home/airflow/.local/lib/python3.8/site-packages/great_expectations/core/usage_statistics/usage_statistics.py", line 266, in usage_statistics_wrapped_method
    result = func(*args, **kwargs)
  File "/home/airflow/.local/lib/python3.8/site-packages/great_expectations/data_context/data_context/abstract_data_context.py", line 2108, in run_checkpoint
    return self._run_checkpoint(
  File "/home/airflow/.local/lib/python3.8/site-packages/great_expectations/data_context/data_context/abstract_data_context.py", line 2152, in _run_checkpoint
    result: CheckpointResult = checkpoint.run_with_runtime_args(
  File "/home/airflow/.local/lib/python3.8/site-packages/great_expectations/checkpoint/checkpoint.py", line 915, in run_with_runtime_args
    return self.run(**checkpoint_run_arguments)
  File "/home/airflow/.local/lib/python3.8/site-packages/great_expectations/core/usage_statistics/usage_statistics.py", line 266, in usage_statistics_wrapped_method
    result = func(*args, **kwargs)
  File "/home/airflow/.local/lib/python3.8/site-packages/great_expectations/checkpoint/checkpoint.py", line 305, in run
    self._run_validation(
  File "/home/airflow/.local/lib/python3.8/site-packages/great_expectations/checkpoint/checkpoint.py", line 550, in _run_validation
    raise gx_exceptions.CheckpointError(
great_expectations.exceptions.exceptions.CheckpointError: Exception occurred while running validation[0] of Checkpoint 'feature_checkpoint': validation action_list cannot be empty.
[2025-07-19T15:58:20.444+0000] {taskinstance.py:1138} INFO - Marking task as FAILED. dag_id=build_ml_features, task_id=validate_features, execution_date=20250719T155311, start_date=20250719T155820, end_date=20250719T155820
[2025-07-19T15:58:20.448+0000] {standard_task_runner.py:107} ERROR - Failed to execute job 159 for task validate_features (Exception occurred while running validation[0] of Checkpoint 'feature_checkpoint': validation action_list cannot be empty.; 942)
[2025-07-19T15:58:20.474+0000] {local_task_job_runner.py:234} INFO - Task exited with return code 1
[2025-07-19T15:58:20.481+0000] {taskinstance.py:3280} INFO - 0 downstream tasks scheduled from follow-on schedule check
