[2025-07-15T22:59:36.133+0000] {taskinstance.py:1956} INFO - Dependencies all met for dep_context=non-requeueable deps ti=<TaskInstance: curated_market_dq.validate_dataframe manual__2025-07-15T22:48:19.926732+00:00 [queued]>
[2025-07-15T22:59:36.154+0000] {taskinstance.py:1956} INFO - Dependencies all met for dep_context=requeueable deps ti=<TaskInstance: curated_market_dq.validate_dataframe manual__2025-07-15T22:48:19.926732+00:00 [queued]>
[2025-07-15T22:59:36.156+0000] {taskinstance.py:2170} INFO - Starting attempt 3 of 3
[2025-07-15T22:59:36.289+0000] {taskinstance.py:2191} INFO - Executing <Task(_PythonDecoratedOperator): validate_dataframe> on 2025-07-15 22:48:19.926732+00:00
[2025-07-15T22:59:36.322+0000] {standard_task_runner.py:60} INFO - Started process 729 to run task
[2025-07-15T22:59:36.343+0000] {standard_task_runner.py:87} INFO - Running: ['***', 'tasks', 'run', 'curated_market_dq', 'validate_dataframe', 'manual__2025-07-15T22:48:19.926732+00:00', '--job-id', '73', '--raw', '--subdir', 'DAGS_FOLDER/curated_market_dq_dag.py', '--cfg-path', '/tmp/tmpikyvega3']
[2025-07-15T22:59:36.349+0000] {standard_task_runner.py:88} INFO - Job 73: Subtask validate_dataframe
[2025-07-15T22:59:36.645+0000] {task_command.py:423} INFO - Running <TaskInstance: curated_market_dq.validate_dataframe manual__2025-07-15T22:48:19.926732+00:00 [running]> on host 933e6b50c7ae
[2025-07-15T22:59:37.663+0000] {taskinstance.py:2480} INFO - Exporting env vars: AIRFLOW_CTX_DAG_OWNER='data-platform' AIRFLOW_CTX_DAG_ID='curated_market_dq' AIRFLOW_CTX_TASK_ID='validate_dataframe' AIRFLOW_CTX_EXECUTION_DATE='2025-07-15T22:48:19.926732+00:00' AIRFLOW_CTX_TRY_NUMBER='3' AIRFLOW_CTX_DAG_RUN_ID='manual__2025-07-15T22:48:19.926732+00:00'
[2025-07-15T22:59:38.423+0000] {file_data_context.py:222} INFO - FileDataContext loading fluent config
[2025-07-15T22:59:38.443+0000] {config.py:187} INFO - Loading 'datasources' ->
[{'assets': [...], 'name': 'local_pandas', 'type': 'pandas'}]
[2025-07-15T22:59:38.472+0000] {fluent_base_model.py:276} INFO - _PandasDataAsset.dict() - missing `config_provider`, skipping config substitution
[2025-07-15T22:59:38.637+0000] {abstract_data_context.py:5515} INFO - Loaded 'local_pandas' from fluent config
[2025-07-15T22:59:38.641+0000] {file_data_context.py:189} WARNING - Could not save project config to disk: [Errno 13] Permission denied: '/opt/***/gx/great_expectations.yml'
[2025-07-15T22:59:38.898+0000] {taskinstance.py:2698} ERROR - Task failed with exception
Traceback (most recent call last):
  File "/home/airflow/.local/lib/python3.8/site-packages/airflow/models/taskinstance.py", line 433, in _execute_task
    result = execute_callable(context=context, **execute_callable_kwargs)
  File "/home/airflow/.local/lib/python3.8/site-packages/airflow/decorators/base.py", line 241, in execute
    return_value = super().execute(context)
  File "/home/airflow/.local/lib/python3.8/site-packages/airflow/operators/python.py", line 199, in execute
    return_value = self.execute_callable()
  File "/home/airflow/.local/lib/python3.8/site-packages/airflow/operators/python.py", line 216, in execute_callable
    return self.python_callable(*self.op_args, **self.op_kwargs)
  File "/opt/airflow/dags/curated_market_dq_dag.py", line 75, in validate_dataframe
    result = ctx.run_checkpoint(
  File "/home/airflow/.local/lib/python3.8/site-packages/great_expectations/core/usage_statistics/usage_statistics.py", line 266, in usage_statistics_wrapped_method
    result = func(*args, **kwargs)
  File "/home/airflow/.local/lib/python3.8/site-packages/great_expectations/data_context/data_context/abstract_data_context.py", line 2108, in run_checkpoint
    return self._run_checkpoint(
  File "/home/airflow/.local/lib/python3.8/site-packages/great_expectations/data_context/data_context/abstract_data_context.py", line 2152, in _run_checkpoint
    result: CheckpointResult = checkpoint.run_with_runtime_args(
  File "/home/airflow/.local/lib/python3.8/site-packages/great_expectations/checkpoint/checkpoint.py", line 915, in run_with_runtime_args
    return self.run(**checkpoint_run_arguments)
  File "/home/airflow/.local/lib/python3.8/site-packages/great_expectations/core/usage_statistics/usage_statistics.py", line 266, in usage_statistics_wrapped_method
    result = func(*args, **kwargs)
  File "/home/airflow/.local/lib/python3.8/site-packages/great_expectations/checkpoint/checkpoint.py", line 315, in run
    self._run_validation(
  File "/home/airflow/.local/lib/python3.8/site-packages/great_expectations/checkpoint/checkpoint.py", line 480, in _run_validation
    validator: Validator = self._validator or self.data_context.get_validator(
  File "/home/airflow/.local/lib/python3.8/site-packages/great_expectations/data_context/data_context/abstract_data_context.py", line 2375, in get_validator
    self.get_batch_list(
  File "/home/airflow/.local/lib/python3.8/site-packages/great_expectations/core/usage_statistics/usage_statistics.py", line 266, in usage_statistics_wrapped_method
    result = func(*args, **kwargs)
  File "/home/airflow/.local/lib/python3.8/site-packages/great_expectations/data_context/data_context/abstract_data_context.py", line 2544, in get_batch_list
    return self._get_batch_list(
  File "/home/airflow/.local/lib/python3.8/site-packages/great_expectations/data_context/data_context/abstract_data_context.py", line 2625, in _get_batch_list
    return datasource.get_batch_list_from_batch_request(batch_request=result)
  File "/home/airflow/.local/lib/python3.8/site-packages/great_expectations/datasource/fluent/interfaces.py", line 474, in get_batch_list_from_batch_request
    return data_asset.get_batch_list_from_batch_request(batch_request)
  File "/home/airflow/.local/lib/python3.8/site-packages/great_expectations/datasource/fluent/pandas_datasource.py", line 410, in get_batch_list_from_batch_request
    self._validate_batch_request(batch_request)
  File "/home/airflow/.local/lib/python3.8/site-packages/great_expectations/datasource/fluent/pandas_datasource.py", line 201, in _validate_batch_request
    and not batch_request.options
AttributeError: 'RuntimeBatchRequest' object has no attribute 'options'
[2025-07-15T22:59:38.980+0000] {taskinstance.py:1138} INFO - Marking task as FAILED. dag_id=curated_market_dq, task_id=validate_dataframe, execution_date=20250715T224819, start_date=20250715T225936, end_date=20250715T225938
[2025-07-15T22:59:39.079+0000] {standard_task_runner.py:107} ERROR - Failed to execute job 73 for task validate_dataframe ('RuntimeBatchRequest' object has no attribute 'options'; 729)
[2025-07-15T22:59:39.161+0000] {local_task_job_runner.py:234} INFO - Task exited with return code 1
[2025-07-15T22:59:39.229+0000] {taskinstance.py:3280} INFO - 0 downstream tasks scheduled from follow-on schedule check
