[2025-07-19T14:07:18.865+0000] {taskinstance.py:1956} INFO - Dependencies all met for dep_context=non-requeueable deps ti=<TaskInstance: build_ml_features.validate_features manual__2025-07-19T14:07:12.528373+00:00 [queued]>
[2025-07-19T14:07:18.868+0000] {taskinstance.py:1956} INFO - Dependencies all met for dep_context=requeueable deps ti=<TaskInstance: build_ml_features.validate_features manual__2025-07-19T14:07:12.528373+00:00 [queued]>
[2025-07-19T14:07:18.868+0000] {taskinstance.py:2170} INFO - Starting attempt 1 of 2
[2025-07-19T14:07:18.876+0000] {taskinstance.py:2191} INFO - Executing <Task(_PythonDecoratedOperator): validate_features> on 2025-07-19 14:07:12.528373+00:00
[2025-07-19T14:07:18.882+0000] {standard_task_runner.py:60} INFO - Started process 303 to run task
[2025-07-19T14:07:18.884+0000] {standard_task_runner.py:87} INFO - Running: ['***', 'tasks', 'run', 'build_ml_features', 'validate_features', 'manual__2025-07-19T14:07:12.528373+00:00', '--job-id', '96', '--raw', '--subdir', 'DAGS_FOLDER/build_ml_features_dag.py', '--cfg-path', '/tmp/tmpzhqsxub3']
[2025-07-19T14:07:18.885+0000] {standard_task_runner.py:88} INFO - Job 96: Subtask validate_features
[2025-07-19T14:07:18.906+0000] {task_command.py:423} INFO - Running <TaskInstance: build_ml_features.validate_features manual__2025-07-19T14:07:12.528373+00:00 [running]> on host f0ff35199671
[2025-07-19T14:07:18.946+0000] {taskinstance.py:2480} INFO - Exporting env vars: AIRFLOW_CTX_DAG_OWNER='data-platform' AIRFLOW_CTX_DAG_ID='build_ml_features' AIRFLOW_CTX_TASK_ID='validate_features' AIRFLOW_CTX_EXECUTION_DATE='2025-07-19T14:07:12.528373+00:00' AIRFLOW_CTX_TRY_NUMBER='1' AIRFLOW_CTX_DAG_RUN_ID='manual__2025-07-19T14:07:12.528373+00:00'
[2025-07-19T14:07:18.978+0000] {file_data_context.py:222} INFO - FileDataContext loading fluent config
[2025-07-19T14:07:18.979+0000] {config.py:187} INFO - Loading 'datasources' ->
[{'assets': [...], 'name': 'local_pandas', 'type': 'pandas'}]
[2025-07-19T14:07:18.980+0000] {fluent_base_model.py:276} INFO - _PandasDataAsset.dict() - missing `config_provider`, skipping config substitution
[2025-07-19T14:07:18.995+0000] {abstract_data_context.py:5515} INFO - Loaded 'local_pandas' from fluent config
[2025-07-19T14:07:18.995+0000] {file_data_context.py:174} INFO - Saving 1 Fluent Datasources to /opt/***/gx/great_expectations.yml
[2025-07-19T14:07:18.996+0000] {fluent_base_model.py:276} INFO - DataFrameAsset.dict() - missing `config_provider`, skipping config substitution
[2025-07-19T14:07:18.996+0000] {fluent_base_model.py:276} INFO - PandasDatasource.dict() - missing `config_provider`, skipping config substitution
[2025-07-19T14:07:19.026+0000] {taskinstance.py:2698} ERROR - Task failed with exception
Traceback (most recent call last):
  File "/home/airflow/.local/lib/python3.8/site-packages/great_expectations/datasource/fluent/interfaces.py", line 510, in get_asset
    found_asset: _DataAssetT = list(
IndexError: list index out of range

The above exception was the direct cause of the following exception:

Traceback (most recent call last):
  File "/home/airflow/.local/lib/python3.8/site-packages/airflow/models/taskinstance.py", line 433, in _execute_task
    result = execute_callable(context=context, **execute_callable_kwargs)
  File "/home/airflow/.local/lib/python3.8/site-packages/airflow/decorators/base.py", line 241, in execute
    return_value = super().execute(context)
  File "/home/airflow/.local/lib/python3.8/site-packages/airflow/operators/python.py", line 199, in execute
    return_value = self.execute_callable()
  File "/home/airflow/.local/lib/python3.8/site-packages/airflow/operators/python.py", line 216, in execute_callable
    return self.python_callable(*self.op_args, **self.op_kwargs)
  File "/opt/airflow/dags/build_ml_features_dag.py", line 97, in validate_features
    asset = ctx.datasources["local_pandas"].get_asset("features_v1")
  File "/home/airflow/.local/lib/python3.8/site-packages/great_expectations/datasource/fluent/interfaces.py", line 516, in get_asset
    raise LookupError(
LookupError: "features_v1" not found. Available assets are (spy_sample)
[2025-07-19T14:07:19.031+0000] {taskinstance.py:1138} INFO - Marking task as UP_FOR_RETRY. dag_id=build_ml_features, task_id=validate_features, execution_date=20250719T140712, start_date=20250719T140718, end_date=20250719T140719
[2025-07-19T14:07:19.035+0000] {standard_task_runner.py:107} ERROR - Failed to execute job 96 for task validate_features ("features_v1" not found. Available assets are (spy_sample); 303)
[2025-07-19T14:07:19.066+0000] {local_task_job_runner.py:234} INFO - Task exited with return code 1
[2025-07-19T14:07:19.075+0000] {taskinstance.py:3280} INFO - 0 downstream tasks scheduled from follow-on schedule check
