[2025-07-13T15:10:19.296+0000] {taskinstance.py:1956} INFO - Dependencies all met for dep_context=non-requeueable deps ti=<TaskInstance: transform_market_data.transform_market_data manual__2025-07-13T15:05:06.704568+00:00 [queued]>
[2025-07-13T15:10:19.317+0000] {taskinstance.py:1956} INFO - Dependencies all met for dep_context=requeueable deps ti=<TaskInstance: transform_market_data.transform_market_data manual__2025-07-13T15:05:06.704568+00:00 [queued]>
[2025-07-13T15:10:19.318+0000] {taskinstance.py:2170} INFO - Starting attempt 2 of 2
[2025-07-13T15:10:19.348+0000] {taskinstance.py:2191} INFO - Executing <Task(PythonOperator): transform_market_data> on 2025-07-13 15:05:06.704568+00:00
[2025-07-13T15:10:19.363+0000] {standard_task_runner.py:60} INFO - Started process 162 to run task
[2025-07-13T15:10:19.374+0000] {standard_task_runner.py:87} INFO - Running: ['***', 'tasks', 'run', 'transform_market_data', 'transform_market_data', 'manual__2025-07-13T15:05:06.704568+00:00', '--job-id', '16', '--raw', '--subdir', 'DAGS_FOLDER/transform_market_data_dag.py', '--cfg-path', '/tmp/tmpjr73l6vr']
[2025-07-13T15:10:19.376+0000] {standard_task_runner.py:88} INFO - Job 16: Subtask transform_market_data
[2025-07-13T15:10:19.511+0000] {task_command.py:423} INFO - Running <TaskInstance: transform_market_data.transform_market_data manual__2025-07-13T15:05:06.704568+00:00 [running]> on host 26c08c9ca2cf
[2025-07-13T15:10:19.871+0000] {taskinstance.py:2480} INFO - Exporting env vars: AIRFLOW_CTX_DAG_OWNER='mark' AIRFLOW_CTX_DAG_ID='transform_market_data' AIRFLOW_CTX_TASK_ID='transform_market_data' AIRFLOW_CTX_EXECUTION_DATE='2025-07-13T15:05:06.704568+00:00' AIRFLOW_CTX_TRY_NUMBER='2' AIRFLOW_CTX_DAG_RUN_ID='manual__2025-07-13T15:05:06.704568+00:00'
[2025-07-13T15:10:19.929+0000] {credentials.py:1147} INFO - Found credentials in environment variables.
[2025-07-13T15:10:20.454+0000] {taskinstance.py:2698} ERROR - Task failed with exception
Traceback (most recent call last):
  File "/home/airflow/.local/lib/python3.8/site-packages/airflow/models/taskinstance.py", line 433, in _execute_task
    result = execute_callable(context=context, **execute_callable_kwargs)
  File "/home/airflow/.local/lib/python3.8/site-packages/airflow/operators/python.py", line 199, in execute
    return_value = self.execute_callable()
  File "/home/airflow/.local/lib/python3.8/site-packages/airflow/operators/python.py", line 216, in execute_callable
    return self.python_callable(*self.op_args, **self.op_kwargs)
  File "/opt/airflow/dags/transform_market_data_dag.py", line 15, in transform_yfinance_data
    obj = s3.get_object(Bucket=bucket, Key=key)
  File "/home/airflow/.local/lib/python3.8/site-packages/botocore/client.py", line 553, in _api_call
    return self._make_api_call(operation_name, kwargs)
  File "/home/airflow/.local/lib/python3.8/site-packages/botocore/client.py", line 1009, in _make_api_call
    raise error_class(parsed_response, operation_name)
botocore.errorfactory.NoSuchKey: An error occurred (NoSuchKey) when calling the GetObject operation: The specified key does not exist.
[2025-07-13T15:10:20.478+0000] {taskinstance.py:1138} INFO - Marking task as FAILED. dag_id=transform_market_data, task_id=transform_market_data, execution_date=20250713T150506, start_date=20250713T151019, end_date=20250713T151020
[2025-07-13T15:10:20.507+0000] {standard_task_runner.py:107} ERROR - Failed to execute job 16 for task transform_market_data (An error occurred (NoSuchKey) when calling the GetObject operation: The specified key does not exist.; 162)
[2025-07-13T15:10:20.563+0000] {local_task_job_runner.py:234} INFO - Task exited with return code 1
[2025-07-13T15:10:20.605+0000] {taskinstance.py:3280} INFO - 0 downstream tasks scheduled from follow-on schedule check
