[2025-07-13T04:39:21.756+0000] {taskinstance.py:1956} INFO - Dependencies all met for dep_context=non-requeueable deps ti=<TaskInstance: s3_ingestion.upload_to_s3 manual__2025-07-13T04:39:13.118437+00:00 [queued]>
[2025-07-13T04:39:21.778+0000] {taskinstance.py:1956} INFO - Dependencies all met for dep_context=requeueable deps ti=<TaskInstance: s3_ingestion.upload_to_s3 manual__2025-07-13T04:39:13.118437+00:00 [queued]>
[2025-07-13T04:39:21.779+0000] {taskinstance.py:2170} INFO - Starting attempt 1 of 2
[2025-07-13T04:39:21.815+0000] {taskinstance.py:2191} INFO - Executing <Task(PythonOperator): upload_to_s3> on 2025-07-13 04:39:13.118437+00:00
[2025-07-13T04:39:21.824+0000] {standard_task_runner.py:60} INFO - Started process 2968 to run task
[2025-07-13T04:39:21.830+0000] {standard_task_runner.py:87} INFO - Running: ['***', 'tasks', 'run', 's3_ingestion', 'upload_to_s3', 'manual__2025-07-13T04:39:13.118437+00:00', '--job-id', '4', '--raw', '--subdir', 'DAGS_FOLDER/s3_ingestion_dag.py', '--cfg-path', '/tmp/tmpsbg_3z1j']
[2025-07-13T04:39:21.834+0000] {standard_task_runner.py:88} INFO - Job 4: Subtask upload_to_s3
[2025-07-13T04:39:21.922+0000] {task_command.py:423} INFO - Running <TaskInstance: s3_ingestion.upload_to_s3 manual__2025-07-13T04:39:13.118437+00:00 [running]> on host a01d149c224b
[2025-07-13T04:39:22.150+0000] {taskinstance.py:2480} INFO - Exporting env vars: AIRFLOW_CTX_DAG_OWNER='mark' AIRFLOW_CTX_DAG_ID='s3_ingestion' AIRFLOW_CTX_TASK_ID='upload_to_s3' AIRFLOW_CTX_EXECUTION_DATE='2025-07-13T04:39:13.118437+00:00' AIRFLOW_CTX_TRY_NUMBER='1' AIRFLOW_CTX_DAG_RUN_ID='manual__2025-07-13T04:39:13.118437+00:00'
[2025-07-13T04:39:24.753+0000] {taskinstance.py:2698} ERROR - Task failed with exception
Traceback (most recent call last):
  File "/home/airflow/.local/lib/python3.8/site-packages/airflow/models/taskinstance.py", line 433, in _execute_task
    result = execute_callable(context=context, **execute_callable_kwargs)
  File "/home/airflow/.local/lib/python3.8/site-packages/airflow/operators/python.py", line 199, in execute
    return_value = self.execute_callable()
  File "/home/airflow/.local/lib/python3.8/site-packages/airflow/operators/python.py", line 216, in execute_callable
    return self.python_callable(*self.op_args, **self.op_kwargs)
  File "/opt/airflow/dags/s3_ingestion_dag.py", line 8, in upload_to_s3
    with open('/app/data/dataset.csv', 'rb') as f:
FileNotFoundError: [Errno 2] No such file or directory: '/app/data/dataset.csv'
[2025-07-13T04:39:24.787+0000] {taskinstance.py:1138} INFO - Marking task as UP_FOR_RETRY. dag_id=s3_ingestion, task_id=upload_to_s3, execution_date=20250713T043913, start_date=20250713T043921, end_date=20250713T043924
[2025-07-13T04:39:24.852+0000] {standard_task_runner.py:107} ERROR - Failed to execute job 4 for task upload_to_s3 ([Errno 2] No such file or directory: '/app/data/dataset.csv'; 2968)
[2025-07-13T04:39:24.916+0000] {local_task_job_runner.py:234} INFO - Task exited with return code 1
[2025-07-13T04:39:25.033+0000] {taskinstance.py:3280} INFO - 0 downstream tasks scheduled from follow-on schedule check
